<mujoco>
  <body name="base" pos="0.100 0.950 0.780" quat="-0.707 0.000 0.000 0.707" childclass="ur10e">
    <inertial mass="4.0" pos="0 0 0" diaginertia="0.0061063308908 0.0061063308908 0.01125"/>
    <geom mesh="base_0" material="black" class="visual"/>
    <geom mesh="base_1" material="jointgray" class="visual"/>
    <body name="shoulder_link" pos="0 0 0.181">
      <inertial pos="0 0 0" mass="7.778" diaginertia="0.0314743 0.0314743 0.0218756"/>
      <joint name="shoulder_pan_joint" class="size4" axis="0 0 1"/>
      <geom mesh="shoulder_0" material="urblue" class="visual"/>
      <geom mesh="shoulder_1" material="black" class="visual"/>
      <geom mesh="shoulder_2" material="jointgray" class="visual"/>
      <geom class="collision" size="0.078 0.08" pos="0 0 -0.05"/>
      <body name="upper_arm_link" pos="0 0.176 0" quat="1 0 1 0">
        <inertial pos="0 0 0.3065" mass="12.93" diaginertia="0.423074 0.423074 0.0363656"/>
        <joint name="shoulder_lift_joint" class="size4"/>
        <geom mesh="upperarm_0" material="black" class="visual"/>
        <geom mesh="upperarm_1" material="jointgray" class="visual"/>
        <geom mesh="upperarm_2" material="urblue" class="visual"/>
        <geom mesh="upperarm_3" material="linkgray" class="visual"/>
        <geom class="collision" pos="0 -0.05 0" quat="1 1 0 0" size="0.078 0.08"/>
        <geom class="collision" size="0.06 0.3" pos="0 0 0.3"/>
        <body name="forearm_link" pos="0 -0.137 0.613">
          <inertial pos="0 0 0.2855" mass="3.87" diaginertia="0.11059 0.11059 0.0108844"/>
          <joint name="elbow_joint" class="size3_limited"/>
          <geom mesh="forearm_0" material="urblue" class="visual"/>
          <geom mesh="forearm_1" material="black" class="visual"/>
          <geom mesh="forearm_2" material="jointgray" class="visual"/>
          <geom mesh="forearm_3" material="linkgray" class="visual"/>
          <geom class="collision" pos="0 0.08 0" quat="1 1 0 0" size="0.058 0.065"/>
          <geom class="collision" size="0.043 0.28" pos="0 0 0.29"/>
          <body name="wrist_1_link" pos="0 0 0.571" quat="1 0 1 0">
            <inertial pos="0 0.135 0" quat="0.5 0.5 -0.5 0.5" mass="1.96"
              diaginertia="0.0055125 0.00510825 0.00510825"/>
            <joint name="wrist_1_joint" class="size2"/>
            <geom mesh="wrist1_0" material="black" class="visual"/>
            <geom mesh="wrist1_1" material="urblue" class="visual"/>
            <geom mesh="wrist1_2" material="jointgray" class="visual"/>
            <geom class="collision" pos="0 0.06 0" quat="1 1 0 0" size="0.05 0.07"/>
            <body name="wrist_2_link" pos="0 0.135 0">
              <inertial pos="0 0 0.12" quat="0.5 0.5 -0.5 0.5" mass="1.96"
                diaginertia="0.0055125 0.00510825 0.00510825"/>
              <joint name="wrist_2_joint" axis="0 0 1" class="size2"/>
              <geom mesh="wrist2_0" material="black" class="visual"/>
              <geom mesh="wrist2_1" material="urblue" class="visual"/>
              <geom mesh="wrist2_2" material="jointgray" class="visual"/>
              <geom class="collision" size="0.046 0.065" pos="0 0 0.05"/>
              <geom class="collision" pos="0 0.028 0.12" quat="1 1 0 0" size="0.046 0.043"/>
              <body name="wrist_3_link" pos="0 0 0.12">
                <inertial pos="0 0.092 0" quat="0 1 -1 0" mass="0.202"
                  diaginertia="0.000204525 0.000144346 0.000144346"/>
                <joint name="wrist_3_joint" class="size2"/>
                <geom material="linkgray" mesh="wrist3" class="visual"/>
                <geom class="eef_collision" pos="0 0.097 0" quat="1 1 0 0" size="0.046 0.02"/>
                <body name="tool0_link" pos="0 0.115 0" quat="1 -1 0 0 ">
                  <geom name="blue_sensor" pos="0 0 0.025" size="0.04 0.025" rgba="0.0118 0.5176 0.6706 1" type="cylinder"/>
                  <body name="blue_sensor_end" pos="0 0 0.05" quat="1 0 0 0">
                    <include file="robotiq_2f_140_body.xml"></include>
                  </body>
                </body>
              </body>
            </body>
          </body>
        </body>
      </body>
    </body>
  </body>
</mujoco>
